Workbook
Name v_drv_dwell_time: HeroStore!$D$2
Name v_drv_balk_rate: HeroStore!$D$3
Name v_drv_open_hours: HeroStore!$D$4
Name v_drv_rent: HeroStore!$D$5
Name v_prd_meat_price: HeroStore!$D$11
Name v_prd_portion_grams: HeroStore!$D$12
Name v_prd_portions_per_cover: HeroStore!$D$13
Name v_prd_alcohol_price: HeroStore!$D$14
Name v_prd_alcohol_per_cover: HeroStore!$D$15
Name v_prd_side_spend_per_cover: HeroStore!$D$16
Name v_prd_menu_count: HeroStore!$D$17
Name v_svc_banchan_count: HeroStore!$D$19
Name v_cst_banchan_cost_per_cover: HeroStore!$D$20
Name v_mkt_celebrity_visits: HeroStore!$D$28
Name v_mkt_price_elasticity: HeroStore!$D$31
Name v_mkt_party_size: HeroStore!$D$32
Name v_mkt_patience: HeroStore!$D$33
Name v_seg_twenties_party_factor: HeroStore!$D$34
Name v_seg_twenties_dwell_factor: HeroStore!$D$35
Name v_seg_twenties_alcohol_factor: HeroStore!$D$36
Name v_seg_twenties_patience_factor: HeroStore!$D$37
Name v_seg_twenties_early_mult: HeroStore!$D$38
Name v_seg_twenties_late_mult: HeroStore!$D$39
Name v_seg_office_party_factor: HeroStore!$D$40
Name v_seg_office_dwell_factor: HeroStore!$D$41
Name v_seg_office_alcohol_factor: HeroStore!$D$42
Name v_seg_office_patience_factor: HeroStore!$D$43
Name v_seg_office_early_mult: HeroStore!$D$44
Name v_seg_office_late_mult: HeroStore!$D$45
Name v_seg_family_party_factor: HeroStore!$D$46
Name v_seg_family_dwell_factor: HeroStore!$D$47
Name v_seg_family_alcohol_factor: HeroStore!$D$48
Name v_seg_family_patience_factor: HeroStore!$D$49
Name v_seg_family_early_mult: HeroStore!$D$50
Name v_seg_family_late_mult: HeroStore!$D$51
Name v_reg_age_mix: HeroStore!$D$52
Name v_reg_evening_share: HeroStore!$D$53
Name v_reg_competitors: HeroStore!$D$57
Name v_cst_meat_cost_per_portion: HeroStore!$D$58
Name v_cst_alcohol_cost_per_bottle: HeroStore!$D$59
Name v_cst_side_cost_ratio: HeroStore!$D$60
Name v_cst_employee_wage: HeroStore!$D$61
Name v_cst_owner_imputed_wage: HeroStore!$D$62
Name v_cst_holiday_pay_factor: HeroStore!$D$63
Name v_cst_utilities: HeroStore!$D$64
Name v_cst_other_opex: HeroStore!$D$65
Name v_cst_card_share: HeroStore!$D$66
Name v_cst_card_fee_rate: HeroStore!$D$67
Name v_sto_area_pyeong: HeroStore!$D$68
Name v_sto_tables: HeroStore!$D$69
Name v_sto_seats_per_table: HeroStore!$D$70
Name v_sto_terrace: HeroStore!$D$71
Name v_sto_terrace_availability: HeroStore!$D$72
Name v_wx_rain_nights_share: HeroStore!$D$73
Name v_wx_rain_arrival_effect: HeroStore!$D$74
Name v_sto_occupancy: HeroStore!$D$75
Name v_sto_table_turns: HeroStore!$D$76
Name v_sto_open_days: HeroStore!$D$77
Name v_sto_parttimers: HeroStore!$D$78
Name v_sto_parttime_wage: HeroStore!$D$79

Sheet README
A1: 대학로 삼겹살집 디지털 트윈: 리서치 입력 워크북
A2: composite 미도입 독립 삼겹살집 (대학로·혜화역 상권 3120012). 실제 상호 없음. 모든 추정값은 예시(ILLUSTRATIVE)이며 검토 전까지 사실이 아님.
A4: 작성 방법
A5: 1. HeroStore 시트에서 한 행 = 한 기준(criterion). low / base / high 를 채우고, reasoning_chain 에 한 줄 계산 근거를 적는다 (예: 43석 × 0.70 × 1.25회전 × ₩28,000 × 26일).
A6: 2. source_id 는 Sources 시트의 ID만 사용. 출처가 없으면 source_id 를 비우고 confidence 를 반드시 L 로 둔다.
A7: 3. confidence: H = 공공데이터·공식 수치 / M = 기사·보고서 근거 / L = 가정 또는 약한 근거.
A8: 4. filled_by 에 채운 사람(AI 또는 이름)을 적는다.
A9: 5. 규칙: AI가 채운 칸은 반드시 사람이 검토하고 reviewed_by에 이름을 적는다. 검토 전 값은 발표·시뮬레이션 결론에 쓰지 않는다.
A10: 6. P&L, Checks 시트는 수식이다. 숫자를 직접 입력하지 말 것. HeroStore base 값을 바꾸면 자동으로 다시 계산된다.
A11: 7. Checks 시트의 PASS/FAIL 행이 모두 PASS 인지 확인한다 (앵커 ₩2,580만 ±40%, 인건비·기타 비용·영업이익률은 KREI ±5pp). 식재료·임차료·주류 비중은 INFO 행으로 차이만 보여 준다.
A12: 8. 새 기준을 추가하려면 ontology/criteria.csv 에 먼저 추가하고 build_workbook.py 를 다시 실행한다 (시트에만 추가하면 로더가 무시).
A14: 색상 범례
... A29: 주의: 임차료(R-ONE)와 고기 원가(KMTA)는 이제 실제 시세다. 반찬 원가와 일부 기타 비용은 아직 출처가 없다. 전국 KREI 비중과 다른 부분은 대학로의 특징으로 본다.

Sheet Criteria
A1: criterion_id | B1: name_ko | C1: name_en | D1: category | E1: driver_node | F1: unit | G1: data_type | H1: method | I1: source_id | J1: industry_scope | K1: in_sim | L1: notes
A2: drv_operating_profit | B2: 영업이익 | C2: Operating profit | D2: 성과 | F2: ₩/월 | G2: number | H2: derived | I2: S31 | J2: generic | K2: Y | L2: Root. 영업이익 = 매출 − 총비용. KREI measures OP after imputed owner wage. Simulation output; not a label
A3: drv_revenue | B3: 매출 | C3: Revenue | D3: 성과 | E3: drv_operating_profit | F3: ₩/월 | G3: number | H3: derived | I3: S12;S13 | J3: generic | K3: Y | L3: Team doc: 매출. = 착석고객수 × 객단가 × 영업일수. Calibrated to the 대학로 한식 ₩2580만/점포·월 anchor
A4: drv_total_cost | B4: 총비용 | C4: Total operating cost | D4: Cost | E4: drv_operating_profit | F4: ₩/월 | G4: number | H4: derived | I4: S31 | J4: generic | K4: Y | L4: Team doc: Cost. Sum of the five cost lines
A5: drv_covers | B5: 착석고객수 | C5: Seated covers | D5: 성과 | E5: drv_revenue | F5: 명/일 | G5: number | H5: derived | J5: generic | K5: Y | L5: Static P&L: 유효좌석 × 점유율 × 회전율. Simulation: output of arrivals/dwell/balking
A6: drv_ticket | B6: 객단가 | C6: Spend per cover | D6: 성과 | E6: drv_revenue | F6: ₩/인 | G6: number | H6: derived | I6: S28;S25 | J6: bbq | K6: Y | L6: = 인분/인 × 고기가 + 병/인 × 주류가 + 식사·사이드. BBQ template composition
A7: drv_arrival_rate | B7: 도착률 | C7: Arrival rate | D7: 지역 | E7: drv_covers | F7: 팀/일 | G7: number | H7: derived | I7: S12 | J7: generic | K7: Y | L7: Static: 착석고객수 ÷ (1 − 대기이탈률) ÷ 일행 수. Simulation: NHPP with hourly shape from S12 time bands
A8: drv_seats | B8: 좌석수 | C8: Effective seats | D8: 가게현황 | E8: drv_covers | F8: 석 | G8: number | H8: derived | I8: S34 | J8: generic | K8: Y | L8: = 테이블 × 테이블당 의자 + 야장 좌석 × 야장 가용률
A9: drv_dwell_time | B9: 체류시간 | C9: Dwell time | D9: 서비스 | E9: drv_covers | F9: 분 | G9: number | H9: guesstimate | I9: S71;S72;S73 | J9: bbq | K9: Y | L9: Team doc: 고객 체류시간. No Korean measurement; bounded by AYCE caps (100-120 min) and US casual dining (47 min)
A10: drv_balk_rate | B10: 대기이탈률 | C10: Balking rate | D10: 서비스 | E10: drv_covers | F10: 비율 | G10: number | H10: guesstimate | J10: generic | K10: Y | L10: Prior only; the simulation produces it from patience vs wait
A11: drv_open_hours | B11: 영업시간 | C11: Opening hours | D11: 가게현황 | E11: drv_covers | F11: 시간/일 | G11: number | H11: guesstimate | I11: S12;S35 | J11: generic | K11: Y | L11: 17:00–24:00 evening store; 63% of 대학로 한식 sales fall 17–24
A12: drv_food_cost | B12: 식재료비 | C12: Food & beverage cost | D12: Cost | E12: drv_total_cost | F12: ₩/월 | G12: number | H12: derived | I12: S31 | J12: generic | K12: Y | L12: Meat + alcohol + meal/side + banchan cost per cover × covers
A13: drv_labor_cost | B13: 인건비 | C13: Labor cost | D13: Cost | E13: drv_total_cost | F13: ₩/월 | G13: number | H13: derived | I13: S31;S32;S36 | J13: generic | K13: Y | L13: Team doc: 인건비. 알바 + 정직원 + 대표자 귀속 인건비 (KREI convention)
A14: drv_rent | B14: 임차료 | C14: Rent | D14: Cost | E14: drv_total_cost | F14: ₩/월 | G14: number | H14: public | I14: S52;S53;S55 | J14: generic | K14: Y | L14: R-ONE 혜화동 소규모 상가 1층 rent (2026Q2) x 25평, cash part assuming deposit = 10x monthly rent. About 3x the national level, so the KREI national rent share does not apply
A15: drv_mgmt_cost | B15: 관리비 | C15: Utilities & other opex | D15: Cost | E15: drv_total_cost | F15: ₩/월 | G15: number | H15: derived | I15: S31 | J15: generic | K15: Y | L15: Team doc: 관리비. = 공과금·가스·숯 + 기타경비
A16: drv_fees | B16: 수수료 | C16: Card & platform fees | D16: Cost | E16: drv_total_cost | F16: ₩/월 | G16: number | H16: derived | J16: generic | K16: Y | L16: = 매출 × 카드결제 비중 × 카드수수료율 (+ platform fees if 배달/예약앱 adopted)
A17: prd_meat_origin | B17: 고기 원산지 | C17: Meat origin | D17: 제품 | E17: drv_ticket | F17: 범주 | G17: category | H17: guesstimate | J17: bbq | K17: N | L17: 국내산 / 수입 / 혼합. Price power and meat cost
A18: prd_cut_style | B18: 삼겹살 형태 (대패/냉삼/숙성/통삼) | C18: Pork belly cut style | D18: 제품 | E18: drv_ticket | F18: 범주 | G18: category | H18: guesstimate | J18: bbq | K18: N | L18: Merges team items 대패/냉삼/숙성/통삼 and 통삼겹 (listed twice in the doc)
A19: prd_chobeol | B19: 초벌 여부 | C19: Pre-grilled (초벌) vs raw | D19: 제품 | E19: drv_dwell_time | F19: Y/N | G19: bool | H19: guesstimate | J19: bbq | K19: Y | L19: Team doc: 초벌 or 생. 초벌 shortens table grilling time; adds kitchen labor
A20: prd_signature_side | B20: 특별한 특징 (미나리·고사리 등) | C20: Signature side | D20: 제품 | E20: drv_arrival_rate | F20: 범주 | G20: category | H20: guesstimate | J20: bbq | K20: N | L20: Differentiation → arrivals and upsell
A21: prd_food_quality | B21: 음식의 상태 | C21: Food condition | D21: 제품 | E21: drv_arrival_rate | F21: 점수(1-5) | G21: score | H21: interview_later | I21: S03 | J21: generic | K21: N | L21: Acts through review rating
A22: prd_meat_price | B22: 고기 판매가 | C22: Meat menu price | D22: Cost | E22: drv_ticket | F22: ₩/인분 | G22: number | H22: guesstimate | I22: S23;S24;S25 | J22: bbq | K22: Y | L22: Team doc: 고기 판매가 (Cost category in the doc). 인분 = 200g (참가격 basis). Price shock target
A23: prd_portion_grams | B23: 1인분 중량 | C23: Portion weight | D23: 제품 | E23: drv_ticket | F23: g | G23: number | H23: guesstimate | I23: S23 | J23: bbq | K23: Y | L23: 참가격 basis 200g
A24: prd_portions_per_cover | B24: 1인당 고기 인분 | C24: Meat portions per cover | D24: 제품 | E24: drv_ticket | F24: 인분/인 | G24: number | H24: guesstimate | I24: S28;S74 | J24: bbq | K24: Y | L24: Includes re-orders
A25: prd_alcohol_price | B25: 주류 판매가 (소주) | C25: Soju menu price | D25: Cost | E25: drv_ticket | F25: ₩/병 | G25: number | H25: guesstimate | I25: S25;S26 | J25: generic | K25: Y | L25: Alcohol price shock target
A26: prd_alcohol_per_cover | B26: 1인당 주류 병수 | C26: Bottles per cover | D26: 제품 | E26: drv_ticket | F26: 병/인 | G26: number | H26: guesstimate | I26: S62 | J26: generic | K26: Y | L26: 식약처: 0.85 bottle per drinker per occasion
A27: prd_side_spend_per_cover | B27: 1인당 식사·사이드 매출 | C27: Meal/side spend per cover | D27: 제품 | E27: drv_ticket | F27: ₩/인 | G27: number | H27: guesstimate | I27: S30 | J27: bbq | K27: Y | L27: 냉면·된장찌개·볶음밥 attach
A28: cst_alcohol_meat_ratio | B28: 주류/고기 판매 비율 | C28: Alcohol-to-meat sales ratio | D28: Cost | E28: drv_ticket | F28: 비율 | G28: number | H28: derived | I28: S30 | J28: bbq | K28: Y | L28: Team doc item. Alcohol is the high-margin line (S27)
A29: prd_menu_count | B29: 메뉴 개수 | C29: Menu item count | D29: 가게현황 | E29: drv_food_cost | F29: 개 | G29: number | H29: guesstimate | J29: generic | K29: N | L29: More items → more inventory and waste
A30: svc_staff_grilling | B30: 직원이 구워주는 서비스 | C30: Staff grilling service | D30: 서비스 | E30: drv_dwell_time | F30: Y/N | G30: bool | H30: guesstimate | J30: bbq | K30: Y | L30: Shortens dwell; raises labor; may lift rating
A31: svc_banchan_count | B31: 반찬 가짓수 | C31: Banchan count | D31: 서비스 | E31: drv_food_cost | F31: 가지 | G31: number | H31: guesstimate | J31: generic | K31: N | L31: Team doc: 반찬. Cost enters via cst_banchan_cost_per_cover
A32: cst_banchan_cost_per_cover | B32: 반찬·쌈채소 원가 | C32: Banchan & greens cost per cover | D32: Cost | E32: drv_food_cost | F32: ₩/인 | G32: number | H32: guesstimate | J32: bbq | K32: Y | L32: No source. Originally back-solved from the KREI share with the old meat cost; needs the owner interview
A33: svc_qr_kiosk | B33: QR·키오스크 (미니) | C33: QR / kiosk ordering | D33: 서비스 | E33: drv_labor_cost | F33: Y/N | G33: bool | H33: guesstimate | I33: D0930 | J33: generic | K33: N | L33: Hero = N by scope (미도입). Tech adoption is out of shock scope
A34: svc_corkage | B34: 콜키지 | C34: Corkage | D34: 서비스 | E34: drv_ticket | F34: Y/N | G34: bool | H34: guesstimate | J34: generic | K34: N | L34: Pulls arrivals; lowers alcohol ticket
A35: svc_cleanliness | B35: 청결관리 | C35: Cleanliness | D35: 서비스 | E35: drv_arrival_rate | F35: 점수(1-5) | G35: score | H35: interview_later | J35: generic | K35: N | L35: Acts through review rating
A36: mkt_review_count | B36: 리뷰수 | C36: Review count | D36: 영업·마케팅 | E36: drv_arrival_rate | F36: 건 | G36: number | H36: interview_later | I36: S03;S06 | J36: generic | K36: N | L36: Hand-entered only; Naver Place / 캐치테이블 / 테이블링 must not be scraped
A37: mkt_review_rating | B37: 리뷰 평점 | C37: Review rating | D37: 영업·마케팅 | E37: drv_arrival_rate | F37: 점(1-5) | G37: number | H37: interview_later | I37: S03 | J37: generic | K37: N | L37: Added from literature: +1 star = +5–9% revenue for independents (Luca)
A38: mkt_review_event | B38: 리뷰이벤트 유무 | C38: Review incentive event | D38: 영업·마케팅 | E38: drv_arrival_rate | F38: Y/N | G38: bool | H38: interview_later | J38: generic | K38: N | L38: Raises review count; small giveaway cost
A39: mkt_sponsorship | B39: 마케팅/협찬 여부 | C39: Paid marketing / sponsorship | D39: 영업·마케팅 | E39: drv_arrival_rate | F39: Y/N | G39: bool | H39: interview_later | J39: generic | K39: N | L39: Spend sits in 기타경비
A40: mkt_celebrity_visits | B40: 연예인 방문 비율 | C40: Celebrity visit share | D40: 영업·마케팅 | E40: drv_arrival_rate | F40: 비율 | G40: number | H40: interview_later | J40: generic | K40: N | L40: Rare; demand spike
...

Sheet HeroStore
A1: criterion_id | B1: name_ko | C1: low | D1: base | E1: high | F1: unit | G1: method | H1: reasoning_chain | I1: source_id | J1: confidence | K1: filled_by | L1: reviewed_by | M1: illustrative
A2: drv_dwell_time | B2: 체류시간 | C2: 75 | D2: 105 | E2: 140 | F2: 분 | G2: guesstimate | H2: 국내 측정 없음. 고기 무한리필 체인 이용시간 상한 100~120분(S71), 미국 캐주얼 평균 47분(S72) 사이에서 굽기·음주로 길다고 보고 105분 유지 | I2: S71;S72;S73 | J2: L | K2: AI | M2: ILLUSTRATIVE 예시 추정치 (검토 필요)
A3: drv_balk_rate | B3: 대기이탈률 | C3: 0.003 | D3: 0.01 | E3: 0.05 | F3: 비율 | G3: guesstimate | H3: 시뮬레이션 기준 달의 대기 이탈 손님 비율 ≈1% (python -m sim.calibrate; 인내 25분, 19~21시 피크 가정 반영); 5%는 피크 가정 상한 | J3: L | K3: AI | M3: ILLUSTRATIVE 예시 추정치 (검토 필요)
A4: drv_open_hours | B4: 영업시간 | C4: 6 | D4: 7 | E4: 9 | F4: 시간/일 | G4: guesstimate | H4: 17:00–24:00 = 7h; 대학로 한식 매출 63%가 17–24시(S12); 저녁 전용 삼겹살집 6h 사례(S35) | I4: S12;S35 | J4: M | K4: AI | M4: ILLUSTRATIVE 예시 추정치 (검토 필요)
A5: drv_rent | B5: 임차료 | C5: 3000000 | D5: 4700000 | E5: 5800000 | F5: ₩/월 | G5: public | H5: R-ONE 혜화동 소규모 상가 1층 ₩60,033/㎡/월(2026Q2, 보증금 환산 포함) × 82.64㎡(25평) ÷ 1.0623(보증금 = 월세 10배 가정, 전환율 7.481%) ≈ ₩467만 현금 월세 | I5: S52;S53;S55 | J5: M | K5: AI | M5: 공공데이터/공식 수치
A6: prd_meat_origin | B6: 고기 원산지 | C6: 수입 | D6: 국내산 | E6: 국내산 | F6: 범주 | G6: guesstimate | H6: 대학가 독립점 국내산 삼겹살 가정; 원산지 표시는 인터뷰로 확인 | J6: L | K6: AI | M6: ILLUSTRATIVE 예시 추정치 (검토 필요)
A7: prd_cut_style | B7: 삼겹살 형태 (대패/냉삼/숙성/통삼) | C7: 냉삼/대패 | D7: 일반 생삼겹 | E7: 숙성/통삼 | F7: 범주 | G7: guesstimate | H7: 대학가 저가~중가 독립점의 일반형 가정 | J7: L | K7: AI | M7: ILLUSTRATIVE 예시 추정치 (검토 필요)
A8: prd_chobeol | B8: 초벌 여부 | C8: N | D8: N | E8: Y | F8: Y/N | G8: guesstimate | H8: 생고기 자가 굽기 가정 (초벌은 차별화 옵션) | J8: L | K8: AI | M8: ILLUSTRATIVE 예시 추정치 (검토 필요)
A9: prd_signature_side | B9: 특별한 특징 (미나리·고사리 등) | C9: 없음 | D9: 없음 | E9: 미나리 | F9: 범주 | G9: guesstimate | H9: composite 기본형 = 시그니처 없음 | J9: L | K9: AI | M9: ILLUSTRATIVE 예시 추정치 (검토 필요)
A10: prd_food_quality | B10: 음식의 상태 | F10: 점수(1-5) | G10: interview_later | H10: 인터뷰/방문 평가로 채움 | I10: S03 | J10: L | M10: 대기 (파이프라인 또는 인터뷰로 채움)
A11: prd_meat_price | B11: 고기 판매가 | C11: 17000 | D11: 19000 | E11: 21321 | F11: ₩/인분 | G11: guesstimate | H11: 서울 평균 200g ₩21,321(참가격 2026-06) ~ 골목 ₩17,000(마포 2026-03) → 대학가 독립점 ₩19,000 | I11: S23;S25 | J11: M | K11: AI | M11: ILLUSTRATIVE 예시 추정치 (검토 필요)
A12: prd_portion_grams | B12: 1인분 중량 | C12: 150 | D12: 200 | E12: 200 | F12: g | G12: guesstimate | H12: 참가격 기준 200g; 골목점은 150–180g도 있음 | I12: S23 | J12: M | K12: AI | M12: ILLUSTRATIVE 예시 추정치 (검토 필요)
A13: prd_portions_per_cover | B13: 1인당 고기 인분 | C13: 0.8 | D13: 1 | E13: 1.5 | F13: 인분/인 | G13: guesstimate | H13: 2인 2인분 + 소주 → 1인 1인분 (쿠키뉴스 예시); 성인 남성 4명 6~12인분 일화(S74)로 상한 1.5 | I13: S28;S74 | J13: L | K13: AI | M13: ILLUSTRATIVE 예시 추정치 (검토 필요)
A14: prd_alcohol_price | B14: 주류 판매가 (소주) | C14: 4000 | D14: 5000 | E14: 6000 | F14: ₩/병 | G14: guesstimate | H14: 마포 2026 소주 ₩4,000–6,000의 중간 | I14: S25;S26 | J14: M | K14: AI | M14: ILLUSTRATIVE 예시 추정치 (검토 필요)
A15: prd_alcohol_per_cover | B15: 1인당 주류 병수 | C15: 0.6 | D15: 0.9 | E15: 1.2 | F15: 병/인 | G15: guesstimate | H15: 음주자 1회 평균 소주 6.1잔(50ml) ≈ 0.85병(S62); 비음주 손님과 소맥을 감안해 0.9병 | I15: S62 | J15: L | K15: AI | M15: ILLUSTRATIVE 예시 추정치 (검토 필요)
A16: prd_side_spend_per_cover | B16: 1인당 식사·사이드 매출 | C16: 2000 | D16: 3500 | E16: 5000 | F16: ₩/인 | G16: guesstimate | H16: 식사(냉면·된장 ₩7,000) × 주문률 0.5 = ₩3,500; 식사 비중 15%(블로그) 대조 | I16: S30 | J16: L | K16: AI | M16: ILLUSTRATIVE 예시 추정치 (검토 필요)
A17: prd_menu_count | B17: 메뉴 개수 | C17: 6 | D17: 8 | E17: 12 | F17: 개 | G17: guesstimate | H17: 고기 3–4종 + 식사 2–3종 + 사이드 1–2종 (출처 없음) | J17: L | K17: AI | M17: ILLUSTRATIVE 예시 추정치 (검토 필요)
A18: svc_staff_grilling | B18: 직원이 구워주는 서비스 | C18: N | D18: N | E18: Y | F18: Y/N | G18: guesstimate | H18: 대학가 저가 독립점은 자가 굽기 가정 | J18: L | K18: AI | M18: ILLUSTRATIVE 예시 추정치 (검토 필요)
A19: svc_banchan_count | B19: 반찬 가짓수 | C19: 3 | D19: 5 | E19: 8 | F19: 가지 | G19: guesstimate | H19: 쌈채소·파절이·김치·쌈장·계란찜 가정 | J19: L | K19: AI | M19: ILLUSTRATIVE 예시 추정치 (검토 필요)
A20: cst_banchan_cost_per_cover | B20: 반찬·쌈채소 원가 | C20: 800 | D20: 1200 | E20: 1800 | F20: ₩/인 | G20: guesstimate | H20: 출처 없음. 처음에는 KREI 식재료 37%에서 옛 고기 원가(₩6,500)를 뺀 잔여로 역산한 값이라 고기 원가 교체 후 근거가 없음; 사장님 인터뷰로 확인 | J20: L | K20: AI | M20: ILLUSTRATIVE 예시 추정치 (검토 필요)
A21: svc_qr_kiosk | B21: QR·키오스크 (미니) | C21: N | D21: N | E21: N | F21: Y/N | G21: guesstimate | H21: 미도입 정의상 N (기술 도입은 이번 과제 범위 밖) | I21: D0930 | J21: H | K21: AI | M21: ILLUSTRATIVE 예시 추정치 (검토 필요)
A22: svc_corkage | B22: 콜키지 | C22: N | D22: N | E22: Y | F22: Y/N | G22: guesstimate | H22: 대학가 소주 중심 매장은 콜키지 없음 가정 | J22: L | K22: AI | M22: ILLUSTRATIVE 예시 추정치 (검토 필요)
A23: svc_cleanliness | B23: 청결관리 | F23: 점수(1-5) | G23: interview_later | H23: 방문 점검/인터뷰로 채움 | J23: L | M23: 대기 (파이프라인 또는 인터뷰로 채움)
A24: mkt_review_count | B24: 리뷰수 | F24: 건 | G24: interview_later | H24: composite라 실리뷰 없음; 비교 매장 수기 입력만 (스크래핑 금지) | I24: S03;S06 | J24: L | M24: 대기 (파이프라인 또는 인터뷰로 채움)
A25: mkt_review_rating | B25: 리뷰 평점 | F25: 점(1-5) | G25: interview_later | H25: composite라 실리뷰 없음; 인터뷰 매장 기준 수기 입력 | I25: S03 | J25: L | M25: 대기 (파이프라인 또는 인터뷰로 채움)
A26: mkt_review_event | B26: 리뷰이벤트 유무 | C26: N | D26: N | E26: Y | F26: Y/N | G26: interview_later | H26: 미도입 composite 기본형 = 없음 (인터뷰로 확인) | J26: L | K26: AI | M26: ILLUSTRATIVE 예시 추정치 (검토 필요)
A27: mkt_sponsorship | B27: 마케팅/협찬 여부 | C27: N | D27: N | E27: Y | F27: Y/N | G27: interview_later | H27: 미도입 composite 기본형 = 없음 (인터뷰로 확인) | J27: L | K27: AI | M27: ILLUSTRATIVE 예시 추정치 (검토 필요)
A28: mkt_celebrity_visits | B28: 연예인 방문 비율 | C28: 0 | D28: 0 | E28: 0.01 | F28: 비율 | G28: interview_later | H28: composite 기본형 = 0 (인터뷰로 확인) | J28: L | K28: AI | M28: ILLUSTRATIVE 예시 추정치 (검토 필요)
A29: mkt_waitlist_app | B29: 테이블링/캐치테이블 | C29: N | D29: N | E29: N | F29: Y/N | G29: guesstimate | H29: 미도입 정의상 N | I29: D0930 | J29: H | K29: AI | M29: ILLUSTRATIVE 예시 추정치 (검토 필요)
A30: mkt_delivery | B30: 배달 여부 | C30: N | D30: N | E30: N | F30: Y/N | G30: guesstimate | H30: 미도입 정의상 N (배달 플랫폼 미사용) | I30: D0930 | J30: H | K30: AI | M30: ILLUSTRATIVE 예시 추정치 (검토 필요)
A31: mkt_price_elasticity | B31: 가격탄력성 (도착률) | C31: -0.3 | D31: -0.81 | E31: -2.5 | F31: 탄력성 | G31: guesstimate | H31: −0.81은 외식(FAFH) 범주 수준의 메타분석 평균(S58)이고 한국 음식서비스 범주는 유의하지 않음(S59, 하한 −0.3). 근처 고깃집 27곳 중 한 매장의 탄력성은 범주보다 클 것이라 상한을 −2.5로 넓힘 (매장 수준 값은 출처 없음) | I31: S58;S59 | J31: L | K31: AI | M31: ILLUSTRATIVE 예시 추정치 (검토 필요)
A32: mkt_party_size | B32: 일행 수 | C32: 2.2 | D32: 2.8 | E32: 3.5 | F32: 명/팀 | G32: guesstimate | H32: 국내 일행 분포 없음. 미국 캐주얼 평균 2.61(S72); 대학로 21~24시 결제 1건 ₩60,464 ÷ 1인 ₩2.8만 ≥ 2.2명 → 2.8 유지 (민감도 분석은 SIMULATION.md) | I32: S72;S12 | J32: L | K32: AI | M32: ILLUSTRATIVE 예시 추정치 (검토 필요)
A33: mkt_patience | B33: 대기 인내시간 | C33: 10 | D33: 25 | E33: 35 | F33: 분 | G33: guesstimate | H33: 손님 72%가 30분 넘게 기다리지 않음(S60) → Gamma(형상 4)에서 P(≤30분)=0.72인 평균 ≈ 24.5분 | I33: S60;S61 | J33: L | K33: AI | M33: ILLUSTRATIVE 예시 추정치 (검토 필요)
A34: seg_twenties_party_factor | B34: 20대 친구 모임 일행 규모 계수 | C34: 0.8 | D34: 0.9 | E34: 1 | F34: 배수 | G34: guesstimate | H34: 20대 친구 모임은 2~3명이 많다고 가정 (출처 없음) | J34: L | K34: AI | M34: ILLUSTRATIVE 예시 추정치 (검토 필요)
A35: seg_twenties_dwell_factor | B35: 20대 친구 모임 체류시간 계수 | C35: 0.9 | D35: 1.05 | E35: 1.2 | F35: 배수 | G35: guesstimate | H35: 대화·2차 전 체류가 길다고 가정 (출처 없음) | J35: L | K35: AI | M35: ILLUSTRATIVE 예시 추정치 (검토 필요)
A36: seg_twenties_alcohol_factor | B36: 20대 친구 모임 1인당 음주 계수 | C36: 0.9 | D36: 1.1 | E36: 1.3 | F36: 배수 | G36: guesstimate | H36: 평균보다 약간 더 마신다고 가정 (출처 없음) | J36: L | K36: AI | M36: ILLUSTRATIVE 예시 추정치 (검토 필요)
A37: seg_twenties_patience_factor | B37: 20대 친구 모임 대기 인내 계수 | C37: 1 | D37: 1.3 | E37: 1.6 | F37: 배수 | G37: guesstimate | H37: 소문난 집이면 더 오래 기다린다고 가정 (출처 없음) | J37: L | K37: AI | M37: ILLUSTRATIVE 예시 추정치 (검토 필요)
A38: seg_twenties_early_mult | B38: 20대 친구 모임 이른 저녁(17~19시) 도착 가중치 | C38: 0.4 | D38: 0.6 | E38: 0.9 | F38: 배수 | G38: guesstimate | H38: 수업·알바 뒤 늦게 온다고 가정 (출처 없음) | J38: L | K38: AI | M38: ILLUSTRATIVE 예시 추정치 (검토 필요)
A39: seg_twenties_late_mult | B39: 20대 친구 모임 늦은 밤(21시 이후) 도착 가중치 | C39: 1.2 | D39: 1.6 | E39: 2 | F39: 배수 | G39: guesstimate | H39: 21시 이후 비중이 높다고 가정 (출처 없음) | J39: L | K39: AI | M39: ILLUSTRATIVE 예시 추정치 (검토 필요)
A40: seg_office_party_factor | B40: 직장인 회식 일행 규모 계수 | C40: 1.1 | D40: 1.25 | E40: 1.4 | F40: 배수 | G40: guesstimate | H40: 회식은 3~4명 테이블이 많다고 가정 (출처 없음) | J40: L | K40: AI | M40: ILLUSTRATIVE 예시 추정치 (검토 필요)
...

Sheet Benchmarks
A1: bench_id | B1: name_ko | C1: low | D1: value | E1: high | F1: unit | G1: basis | H1: source_id | I1: note
A2: BM01 | B2: 대학로 한식 연 카드매출 (2025) | D2: 59090000000 | F2: ₩/년 | G2: 3120012 × CS100001, 2025 4개 분기 합 | H2: S12 | I2: 2026-09-30 실측(파이프라인); 연구 파일 반올림 ₩591억
A3: BM02 | B3: 대학로 한식 점포수 (2025Q4) | D3: 191 | F3: 개 | G3: 3120012 × CS100001 | H3: S13 | I3: 프랜차이즈 31
A4: BM03 | B4: 점포당 월매출 앵커 | D4: =$D$2/$D$3/12 | F4: ₩/월 | G4: BM01 ÷ BM02 ÷ 12 | H4: S12;S13 | I4: 보정 목표 (≈₩2,580만)
A5: BM04 | B5: 소형 독립 삼겹살집 월매출 prior | C5: 20000000 | E5: 50000000 | F5: ₩/월 | G5: 전국 평균·사례 기반 working prior | H5: S33;S34;S35 | I5: 서울 돼지고기 통계로는 미검증
A6: BM05 | B6: 전국 육류구이 연매출 (2018) | D6: 225600000 | F6: ₩/년 | G6: KREI 한식 육류요리전문점 | H6: S31
A7: BM06 | B7: 전국 육류구이 월매출 (2018) | D7: =$D$6/12 | F7: ₩/월 | G7: BM05 ÷ 12 | H7: S31 | I7: ≈₩1,880만
A8: BM07 | B8: 대학로 한식 저녁(17–24) 매출 비중 | C8: 0.62 | D8: 0.63 | E8: 0.64 | F8: 비율 | G8: 2025 | H8: S12
A9: BM08 | B9: 대학로 한식 20대 매출 비중 | D9: 0.28 | F9: 비율 | G9: 2025 | H9: S12 | I9: 연령·성별 합계는 법인카드 제외
A10: BM09 | B10: 대학로 한식 30대 매출 비중 | D10: 0.25 | F10: 비율 | G10: 2025 | H10: S12
A11: BM10 | B11: 대학로 돼지고기 구이(I20107) 점포수 | D11: 27 | F11: 개 | G11: 상권 경계 내 점포 좌표 | H11: S20;S18 | I11: 지점명 있는 6개
A12: BM11 | B12: KREI 육류구이 영업이익률 | D12: 0.094 | F12: 매출 대비 | G12: 2018, 전국 | H12: S31 | I12: 대표자 귀속 인건비 차감 후
A13: BM12 | B13: KREI 식재료비 (영업비용 대비) | D13: 0.41 | F13: 비용 대비 | G13: 2018, 전국 | H13: S31
A14: BM13 | B14: KREI 식재료비 (매출 대비) | D14: =$D$13*(1-$D$12) | F14: 매출 대비 | G14: 비용 비중 × (1 − 영업이익률) | H14: S31 | I14: ≈37%
A15: BM14 | B15: KREI 인건비 (영업비용 대비) | D15: 0.342 | F15: 비용 대비 | G15: 2018, 전국 | H15: S31
A16: BM15 | B16: KREI 인건비 (매출 대비) | D16: =$D$15*(1-$D$12) | F16: 매출 대비 | G16: 비용 비중 × (1 − 영업이익률) | H16: S31 | I16: ≈31%
A17: BM16 | B17: KREI 임차료 (영업비용 대비) | D17: 0.093 | F17: 비용 대비 | G17: 2018, 전국 | H17: S31
A18: BM17 | B18: KREI 임차료 (매출 대비) | D18: =$D$17*(1-$D$12) | F18: 매출 대비 | G18: 비용 비중 × (1 − 영업이익률) | H18: S31 | I18: ≈8.4%
A19: BM18 | B19: KREI 기타 비용 (영업비용 대비) | D19: =1-$D$13-$D$15-$D$17 | F19: 비용 대비 | G19: 잔여 = 관리비·수수료·기타 | H19: S31 | I19: 파생값
A20: BM19 | B20: KREI 기타 비용 (매출 대비) | D20: =$D$19*(1-$D$12) | F20: 매출 대비 | G20: 비용 비중 × (1 − 영업이익률) | H20: S31 | I20: ≈14%
A21: BM20 | B21: 외식업 대표자 인건비 (영업비용 대비, 2022) | D21: 0.149 | F21: 비용 대비 | G21: 전체 외식 | H21: S32 | I21: 고용인 14.8%, 가족 3.5%
A22: BM21 | B22: 참가격 삼겹살 200g 서울 (2026-06) | D22: 21321 | F22: ₩/200g | G22: 외식비 공시 | H22: S23 | I22: 전년 대비 +4.3%
A23: BM22 | B23: 참가격 삼겹살 200g 서울 (2026-01) | D23: 21056 | F23: ₩/200g | G23: 외식비 공시 | H23: S24
A24: BM23 | B24: 골목 삼겹살집 가격 (마포 2026-03) | D24: 17000 | F24: ₩/인분 | G24: 기사 사례 | H24: S25 | I24: 중량 미기재
A25: BM24 | B25: 소주 판매가 (마포 2026) | C25: 4000 | E25: 6000 | F25: ₩/병 | G25: 기사 사례 | H25: S25
A26: BM25 | B26: 소주 판매가 (강남 2023) | C26: 7000 | E26: 8000 | F26: ₩/병 | G26: 기사 사례 | H26: S26
A27: BM26 | B27: 소주 식당 마진 (₩6,000 판매 시) | D27: 4400 | F27: ₩/병 | G27: 마진율 73.4% | H27: S27 | I27: 원가 ≈₩1,600
A28: BM27 | B28: 객단가 (주류 포함) | C28: 28000 | E28: 40000 | F28: ₩/인 | G28: 연구 파일 파생값 | H28: S25;S28 | I28: 2인 2인분 + 소주 = ₩5만+
A29: BM28 | B29: 주류 매출 비중 | C29: 0.17 | D29: 0.2 | E29: 0.25 | F29: 비율 | G29: 블로그 65/20/15 + 파생 | H29: S30 | I29: UNVERIFIED
A30: BM29 | B30: 2026 최저임금 | D30: 10320 | F30: ₩/시간 | G30: 법정 | H30: S36 | I30: +2.9%
A31: BM30 | B31: 2026 최저임금 월 환산 (209h) | D31: =$D$30*209 | F31: ₩/월 | G31: BM29 × 209h | H31: S36 | I31: ₩2,156,880
A32: BM31 | B32: KREI 육류구이 종사자 수 | D32: 3.2 | F32: 명 | G32: 2018, 무급가족 18.3% 포함 | H32: S31
A33: BM32 | B33: KREI 육류구이 종사자 1인당 매출 | D33: 70990000 | F33: ₩/년 | G33: 2018 | H33: S31
A34: BM33 | B34: 30평 삼겹살 사례 좌석수 | D34: 60 | F34: 석 | G34: 15테이블, 월 ~₩3,000만 | H34: S34 | I34: 미금(성남) 프랜차이즈
A35: BM34 | B35: 외식업 평균 연매출 (2024) | D35: 255300000 | F35: ₩/년 | G35: 전체 외식 | H35: S33;S29
A36: BM35 | B36: 한식 평균 연매출 (2024) | D36: 291100000 | F36: ₩/년 | G36: 한식 | H36: S33
A37: BM36 | B37: 비프랜차이즈 평균 연매출 (2024) | D37: 230000000 | F37: ₩/년 | G37: 개인 외식업 | H37: S33
A38: BM37 | B38: 한식음식점 5년 생존율 (국세청) | D38: 0.34 | F38: 비율 | G38: 2023, 사업자 폐업 기준 | H38: S38 | I38: 인허가 기준과 정의 다름
A39: BM38 | B39: 서울 한식 3년 생존율 (인허가) | D39: 0.7 | F39: 비율 | G39: LOCALDATA 기준 | H39: S09
A40: BM39 | B40: 서울 외식업 폐업률 (2023) | D40: 0.1899 | F40: 비율 | G40: 핀다 오픈업 | H40: S40 | I40: 민간 추정
...

Sheet P&L
A1: Hero 매장 월 손익 (base case)
A2: ILLUSTRATIVE: 모든 값은 HeroStore base 입력에서 계산된 예시다. 이 시트에 숫자를 직접 입력하지 말 것. KREI 기준 = 2018 전국 육류구이 (매출 대비).
A4: 항목 | B4: 값 | C4: 단위 | D4: 매출 대비 | E4: KREI 기준 | F4: 차이 | G4: 산식·메모
A5: 용량·수요
A6: 유효 좌석수 | B6: =v_sto_tables*v_sto_seats_per_table+v_sto_terrace*v_sto_terrace_availability | C6: 석 | G6: 테이블 × 의자 + 야장 × 가용률
A7: 좌석 점유율 (착석 시) | B7: =v_sto_occupancy | C7: 비율 | G7: HeroStore
A8: 테이블 회전율 | B8: =v_sto_table_turns | C8: 회/일 | G8: HeroStore
A9: 일 착석고객수 | B9: =$B$6*$B$7*$B$8 | C9: 명/일 | G9: 좌석 × 점유율 × 회전율
A10: 월 영업일수 | B10: =v_sto_open_days | C10: 일 | G10: HeroStore
A11: 월 착석고객수 | B11: =$B$9*$B$10 | C11: 명/월
A12: 일 도착 팀수 (이탈 전) | B12: =$B$9/(1-v_drv_balk_rate)/v_mkt_party_size | C12: 팀/일 | G12: 착석 ÷ (1 − 이탈률) ÷ 일행 수
A13: 객단가
A14: 고기 매출 / 인 | B14: =v_prd_portions_per_cover*v_prd_meat_price | C14: ₩/인 | G14: 인분/인 × 고기가
A15: 주류 매출 / 인 | B15: =v_prd_alcohol_per_cover*v_prd_alcohol_price | C15: ₩/인 | G15: 병/인 × 소주가
A16: 식사·사이드 매출 / 인 | B16: =v_prd_side_spend_per_cover | C16: ₩/인 | G16: HeroStore
A17: 객단가 | B17: =$B$14+$B$15+$B$16 | C17: ₩/인 | G17: 합계
A18: 매출
A19: 월 매출 | B19: =$B$11*$B$17 | C19: ₩/월 | D19: 1 | G19: 좌석 × 회전 × 점유율 × 객단가 × 영업일
A20: 고기 매출 | B20: =$B$11*$B$14 | C20: ₩/월 | D20: =$B$20/$B$19
A21: 주류 매출 | B21: =$B$11*$B$15 | C21: ₩/월 | D21: =$B$21/$B$19 | E21: =b_bm28 | F21: =(D21-E21)*100 | G21: 주류 비중 기준: 블로그 20% (미검증)
A22: 식사·사이드 매출 | B22: =$B$11*$B$16 | C22: ₩/월 | D22: =$B$22/$B$19
A23: 주류/고기 판매 비율 | B23: =$B$21/$B$20 | C23: 비율 | G23: cst_alcohol_meat_ratio
A24: 비용
A25: 고기 원가 | B25: =$B$11*v_prd_portions_per_cover*v_cst_meat_cost_per_portion | C25: ₩/월 | D25: =$B$25/$B$19 | G25: 고객 × 인분 × 1인분 원가
A26: 주류 원가 | B26: =$B$11*v_prd_alcohol_per_cover*v_cst_alcohol_cost_per_bottle | C26: ₩/월 | D26: =$B$26/$B$19 | G26: 고객 × 병수 × 병당 원가
A27: 식사·사이드 원가 | B27: =$B$11*v_prd_side_spend_per_cover*v_cst_side_cost_ratio | C27: ₩/월 | D27: =$B$27/$B$19 | G27: 식사 매출 × 원가율
A28: 반찬·쌈채소 원가 | B28: =$B$11*v_cst_banchan_cost_per_cover | C28: ₩/월 | D28: =$B$28/$B$19 | G28: 고객 × 1인 반찬 원가
A29: 식재료비 | B29: =$B$25+$B$26+$B$27+$B$28 | C29: ₩/월 | D29: =$B$29/$B$19 | E29: =b_bm13 | F29: =(D29-E29)*100 | G29: drv_food_cost
A30: 알바 인건비 | B30: =v_sto_parttimers*v_sto_parttime_shift_hours*$B$10*v_sto_parttime_wage*v_cst_holiday_pay_factor | C30: ₩/월 | D30: =$B$30/$B$19 | G30: 알바 수 × 시간 × 영업일 × 시급 × 주휴계수
A31: 정직원 인건비 | B31: =v_sto_employees*v_cst_employee_wage | C31: ₩/월 | D31: =$B$31/$B$19 | G31: 정직원 수 × 월급
A32: 대표자 귀속 인건비 | B32: =v_cst_owner_imputed_wage | C32: ₩/월 | D32: =$B$32/$B$19 | G32: KREI 기준 인건비에 포함
A33: 인건비 | B33: =$B$30+$B$31+$B$32 | C33: ₩/월 | D33: =$B$33/$B$19 | E33: =b_bm15 | F33: =(D33-E33)*100 | G33: drv_labor_cost
A34: 임차료 | B34: =v_drv_rent | C34: ₩/월 | D34: =$B$34/$B$19 | E34: =b_bm17 | F34: =(D34-E34)*100 | G34: drv_rent (R-ONE 혜화동 1층 시세)
A35: 공과금·가스·숯 | B35: =v_cst_utilities | C35: ₩/월 | D35: =$B$35/$B$19
A36: 기타경비 | B36: =v_cst_other_opex | C36: ₩/월 | D36: =$B$36/$B$19
A37: 관리비 | B37: =$B$35+$B$36 | C37: ₩/월 | D37: =$B$37/$B$19 | G37: drv_mgmt_cost
A38: 수수료 | B38: =$B$19*v_cst_card_share*v_cst_card_fee_rate | C38: ₩/월 | D38: =$B$38/$B$19 | G38: 매출 × 카드 비중 × 수수료율
A39: 관리비 + 수수료 | B39: =$B$37+$B$38 | C39: ₩/월 | D39: =$B$39/$B$19 | E39: =b_bm19 | F39: =(D39-E39)*100 | G39: KREI 잔여 비용과 비교
A40: 총비용 | B40: =$B$29+$B$33+$B$34+$B$37+$B$38 | C40: ₩/월 | D40: =$B$40/$B$19 | G40: drv_total_cost
A41: 이익·KPI
...

Sheet Shocks
A1: shock_id | B1: driver | C1: parameter | D1: delta_type | E1: delta_low | F1: delta_base | G1: delta_high | H1: mechanism | I1: source_id | J1: rationale | K1: confidence
A2: SH01 | B2: 가격 | C2: prd_meat_price | D2: pct | E2: 0.05 | F2: 0.1 | G2: 0.15 | H2: 고기 가격이 오르면 객단가는 오르고, 가격탄력성만큼 찾아오는 손님이 줄어든다 | I2: S23;S25 | J2: 인상폭과 가격탄력성(mkt_price_elasticity)은 가정값 | K2: L
A3: SH02 | B3: 가격 | C3: prd_meat_price | D3: pct | E3: -0.05 | F3: -0.1 | G3: -0.15 | H3: 고기 가격이 내리면 객단가는 내려가고, 좌석이 남는 한 손님이 늘어난다 | I3: S23;S25 | J3: 인하폭은 가정값 | K3: L
A4: SH03 | B4: COGS | C4: cst_meat_cost_per_portion | D4: pct | E4: 0.05 | F4: 0.08 | G4: 0.28 | H4: 1인분 원가가 오른다. 사장은 그대로 버티거나 가격에 반영할 수 있다 | I4: S68;S48 | J4: 삼겹 부분육 도매가는 2024년 대비 2025년 +8.1%, 월별 전년 대비 최대 +15%, 1월 대비 8월 +28% | K4: M
A5: SH04 | B5: 주류 | C5: prd_alcohol_price | D5: abs | E5: 500 | F5: 1000 | G5: 1500 | H5: 객단가는 오르고, 1인당 소주 병수는 가격탄력성만큼 줄어든다 | I5: S25;S26;S27 | J5: 소주 4,000~6,000원(마포)과 7,000~8,000원(강남) 사례 | K5: M
A6: SH05 | B6: 주류 | C6: prd_alcohol_per_cover | D6: pct | E6: -0.1 | F6: -0.2 | G6: -0.3 | H6: 주류 매출 비중이 줄어 이익률이 높은 매출이 빠진다 | I6: S27;S30 | J6: 음주 감소 폭은 가정값 | K6: L
A7: SH06 | B7: 인건비 | C7: sto_parttime_wage | D7: pct | E7: 0.029 | F7: 0.05 | G7: 0.1 | H7: 알바 인건비가 오른다 | I7: S36 | J7: 2026년 인상률 2.9%를 하한으로 둔다 | K7: M
A8: SH07 | B8: 인건비 | C8: sto_parttimers | D8: abs | E8: -1 | F8: -1 | G8: -1 | H8: 인건비는 줄지만 서빙 인력이 줄어 대기와 이탈이 늘 수 있다 | I8: S31 | J8: 교대당 알바 1명 감축 | K8: L
A9: SH08 | B9: 임차료 | C9: drv_rent | D9: pct | E9: 0.05 | F9: 0.05 | G9: 0.15 | H9: 재계약 때 임대료가 오르면 고정비가 늘어 손익분기 손님 수가 늘어난다 | I9: S57;S52 | J9: 재계약 때는 법정 상한 5%(환산보증금 9억 이하). +15%는 새로 계약할 때만 가능 | K9: H
A10: SH09 | B10: 수요 | C10: drv_arrival_rate | D10: pct | E10: -0.05 | F10: -0.08 | G10: -0.15 | H10: 방학과 비수기에는 찾아오는 손님이 줄어든다 | I10: S12;S59 | J10: 대학로 한식 3분기 매출은 2분기의 0.96배(전체), 0.92배(21~24시)라 방학 달은 −6%~−11% | K10: H
A11: SH10 | B11: 수요(비) | C11: wx_rain_nights_share | D11: set | E11: 0.13 | F11: 0.19 | G11: 0.35 | H11: 비 오는 밤에는 야장을 접고 손님이 줄어든다. 평년 10월처럼 한 달에 6일쯤 | I11: S75 | J11: 기상청 10월 전국 평년 강수일수 5.9일 (1991~2020) ÷ 31일. 비 오는 밤 손님 감소폭(−10%)은 가정 | K11: M
A12: SH10b | B12: 수요(비) | C12: wx_rain_nights_share | D12: set | E12: 1 | F12: 1 | G12: 1 | H12: 한 달 내내 비가 와 야장을 한 번도 못 펴고 매일 손님이 줄어든다 (최악의 경우) | I12: S75 | J12: 현실적인 달이 아니라 상한. 비 오는 밤 손님 감소폭(−10%)은 가정 | K12: L
A13: SH11 | B13: 경쟁 | C13: reg_competitors | D13: abs | E13: 1 | F13: 1 | G13: 1 | H13: 근처에 경쟁 고깃집이 한 곳 문을 연다 | I13: S20 | J13: 27곳에서 28곳으로 | K13: H
A14: SH11 | B14: 경쟁 | C14: drv_arrival_rate | D14: pct | E14: -0.05 | F14: -0.1 | G14: -0.2 | H14: 거리에 따라 손님을 나눠 갖는다 | I14: S20 | J14: 균등하게 나누면 3.6% 감소, 바로 옆 개점이면 더 크다 (가정) | K14: L

Sheet Edges
A1: from_id | B1: to_id | C1: sign | D1: mechanism_ko | E1: source_id | F1: confidence
A2: drv_revenue | B2: drv_operating_profit | C2: + | D2: 영업이익 = 매출 − 총비용 (항등식) | E2: S31 | F2: H
A3: drv_total_cost | B3: drv_operating_profit | C3: − | D3: 영업이익 = 매출 − 총비용 (항등식) | E3: S31 | F3: H
A4: drv_covers | B4: drv_revenue | C4: + | D4: 매출 = 착석고객수 × 객단가 × 영업일수 | F4: H
A5: drv_ticket | B5: drv_revenue | C5: + | D5: 매출 = 착석고객수 × 객단가 × 영업일수 | F5: H
A6: sto_open_days | B6: drv_revenue | C6: + | D6: 영업일이 늘면 월 매출 비례 증가 | F6: H
A7: drv_arrival_rate | B7: drv_covers | C7: + | D7: 도착 팀이 많을수록 착석 고객 증가 (좌석 한도 내) | F7: H
A8: drv_seats | B8: drv_covers | C8: + | D8: 피크 시간 좌석이 병목이면 좌석 증가 = 착석 증가 | E8: S02 | F8: H
A9: drv_dwell_time | B9: drv_covers | C9: − | D9: 좌석 병목 시 체류가 길면 회전이 줄어 착석 감소 | F9: M
A10: drv_balk_rate | B10: drv_covers | C10: − | D10: 대기 이탈 고객은 착석하지 않음 | F10: H
A11: drv_open_hours | B11: drv_covers | C11: + | D11: 영업시간이 길면 도착 가능 시간대 증가 | E11: S12 | F11: M
A12: sto_occupancy | B12: drv_covers | C12: + | D12: 착석 시 좌석 채움률 (정적 P&L 항) | F12: H
A13: sto_table_turns | B13: drv_covers | C13: + | D13: 하루 회전 수 (정적 P&L 항) | F13: H
A14: drv_dwell_time | B14: sto_table_turns | C14: − | D14: 체류가 길수록 테이블 회전 감소 | F14: M
A15: drv_dwell_time | B15: drv_ticket | C15: + | D15: 오래 머물수록 주류·추가 주문 증가 | F15: L
A16: drv_food_cost | B16: drv_total_cost | C16: + | D16: 비용 항목 합산 | E16: S31 | F16: H
A17: drv_labor_cost | B17: drv_total_cost | C17: + | D17: 비용 항목 합산 | E17: S31 | F17: H
A18: drv_rent | B18: drv_total_cost | C18: + | D18: 비용 항목 합산 | E18: S31 | F18: H
A19: drv_mgmt_cost | B19: drv_total_cost | C19: + | D19: 비용 항목 합산 | E19: S31 | F19: H
A20: drv_fees | B20: drv_total_cost | C20: + | D20: 비용 항목 합산 | F20: H
A21: drv_revenue | B21: drv_fees | C21: + | D21: 카드수수료는 매출에 비례 | F21: H
A22: drv_covers | B22: drv_food_cost | C22: + | D22: 식재료비 = 고객수 × 1인 원가 | F22: H
A23: prd_meat_origin | B23: drv_ticket | C23: ± | D23: 국내산은 가격 프리미엄 가능 / 수입은 저가 포지션 | F23: L
A24: prd_meat_origin | B24: cst_meat_cost_per_portion | C24: + | D24: 국내산 원가가 더 높음 (가정) | F24: L
A25: prd_cut_style | B25: drv_ticket | C25: ± | D25: 숙성·통삼은 고가 / 대패·냉삼은 저가 포지션 | F25: L
A26: prd_cut_style | B26: drv_arrival_rate | C26: ± | D26: 차별화된 형태는 방문 동기 (바이럴) | F26: L
A27: prd_chobeol | B27: drv_dwell_time | C27: − | D27: 초벌이면 테이블 굽는 시간 단축 | F27: M
A28: prd_chobeol | B28: drv_labor_cost | C28: + | D28: 주방 초벌 작업 인력 필요 | F28: L
A29: prd_signature_side | B29: drv_arrival_rate | C29: + | D29: 미나리·고사리 등 시그니처는 차별화·바이럴 | F29: L
A30: prd_signature_side | B30: drv_ticket | C30: + | D30: 곁들임 추가 주문 | F30: L
A31: prd_food_quality | B31: mkt_review_rating | C31: + | D31: 음식 상태가 좋으면 평점 상승 | E31: S03 | F31: M
A32: prd_meat_price | B32: drv_ticket | C32: + | D32: 판매가 인상 = 객단가 상승 | E32: S23 | F32: H
A33: prd_meat_price | B33: drv_arrival_rate | C33: − | D33: 가격 인상 시 가격탄력성만큼 도착 감소 | F33: M
A34: mkt_price_elasticity | B34: drv_arrival_rate | C34: ± | D34: 가격 변화가 도착률에 미치는 크기를 조절 | F34: L
A35: prd_portion_grams | B35: cst_meat_cost_per_portion | C35: + | D35: 1인분 중량이 크면 원가 증가 | F35: H
A36: prd_portion_grams | B36: cst_order_volume | C36: + | D36: 발주량 = 고객 × 인분 × 중량 | F36: H
A37: prd_portions_per_cover | B37: drv_ticket | C37: + | D37: 추가 주문이 많을수록 객단가 상승 | E37: S28 | F37: H
A38: prd_portions_per_cover | B38: drv_food_cost | C38: + | D38: 인분 수 × 1인분 원가 | F38: H
A39: prd_portions_per_cover | B39: cst_order_volume | C39: + | D39: 발주량 = 고객 × 인분 × 중량 | F39: H
A40: prd_alcohol_price | B40: drv_ticket | C40: + | D40: 소주 가격 인상 = 객단가 상승 | E40: S25 | F40: H
...

Sheet Sources
A1: source_id | B1: title | C1: publisher_author | D1: year | E1: url | F1: type | G1: reliability_note
A2: S01 | B2: Why Restaurants Fail | C2: Parsa et al. (Cornell HRAQ) | D2: 2005 | E2: https://econ.ucsb.edu/%7Etedb/Courses/Ec1F07/restaurantsfail.pdf | F2: paper | G2: Peer-reviewed; Columbus OH permits 1996-99; label = ownership turnover; independents 61.36% vs chains 57.22% 3-yr failure
A3: S02 | B3: Why Restaurants Fail Part II | C3: Parsa et al. (J. Foodservice Business Research) | D3: 2011 | E3: https://foodethics.univie.ac.at/fileadmin/user_upload/p_foodethik/Parsa___et.al._2011_Why_Restaurants_Fail_Part_2.pdf | F3: paper | G3: Peer-reviewed; K-M + Cox; size and independence predict closure; US data
A4: S03 | B4: Reviews, Reputation, and Revenue (The Yelp Factor) | C4: Michael Luca (HBS Working Knowledge summary) | E4: https://www.library.hbs.edu/working-knowledge/the-yelp-factor-are-consumer-reviews-good-for-business | F4: paper | G4: Summary page read, not the paper; +1 star = +5-9% revenue for independents; Seattle; year not stated in research file
A5: S04 | B5: Mining Yelp (restaurant closure) | C5: Mejia; Mankad & Gopal (UMD news) | E5: https://rhsmith.umd.edu/news/mining-yelp | F5: news | G5: University news summary of a study; closed yes/no label; DC 2005-14
A6: S05 | B6: Restaurant survival prediction from Yelp | C6: Vallapuram et al. (arXiv) | D6: 2021 | E6: https://www.arxiv.org/pdf/2109.12370 | F6: paper | G6: Preprint; binary open-2017 to dead-2019 label; AUC 0.72
A7: S06 | B7: Review score variance and restaurant survival | C7: Li et al. (Tourism Management; PolyU news) | D7: 2025 | E7: https://www.polyu.edu.hk/shtm/news-and-events/news/2026/20260720_restaurant-reviews/ | F7: paper | G7: Peer-reviewed per news page; variance of review scores predicts 1-yr survival better than mean; Boston
A8: S07 | B8: RevPASH (revenue per available seat-hour) | C8: Sheryl Kimes (Cornell eCommons) | E8: https://ecommons.cornell.edu/entities/publication/519ba198-3b5b-4fa3-84ca-042677dd7a5e | F8: paper | G8: Formula taken from a search summary; the eCommons record itself was not opened (see S47)
A9: S08 | B9: 이태원 음식점 생존분석 | C9: 정동규·윤희연 (대한건축학회) | D9: 2017 | E9: https://laplanning.snu.ac.kr/publication/2017-jeong/ | F9: paper | G9: Peer-reviewed; 폐업 여부 + 영업기간 (K-M + Cox); median survival 골목 2304 vs 발달상권 2748 days
A10: S09 | B10: 서울 카페 생존분석 (LOCALDATA 인허가) | C10: 이채은·최인수 (한국경영공학회지; via dhnews) | D10: 2026 | E10: https://dhnews.co.kr/news/view/1065577402337354 | F10: paper | G10: Read via news article; closure hazard peaks at 24 months; Seoul 한식 3-yr survival ~70%
A11: S10 | B11: 강남구 프랜차이즈 매출 성공 예측 | C11: 안예린 외 (JCCT) | D11: 2022 | E11: https://koreascience.or.kr/article/JAKO202221737437258.pdf | F11: paper | G11: Peer-reviewed; revenue normalized by population; RF accuracy 0.92
A12: S11 | B12: 서울 상권 매출 공간회귀 | C12: 이민주 외 (지역연구) | D12: 2024 | E12: https://koreascience.or.kr/article/JAKO202409378810072.pdf | F12: paper | G12: Peer-reviewed; unit = 상권 not store
A13: S12 | B13: 상권분석서비스 추정매출-상권 (OA-15572 VwsmTrdarSelngQq) | C13: 서울특별시 / 서울신용보증재단 | D13: 2026 | E13: https://data.seoul.go.kr/dataList/OA-15572/S/1/datasetView.do | F13: public_data | G13: Card-based estimate at 상권 x 한식 (CS100001) level; no pork code; 당월_매출_금액 is a quarterly total; 대학로 2025 한식 ₩590.9억 measured live 2026-09-30
A14: S13 | B14: 상권분석서비스 점포-상권 (OA-15577 VwsmTrdarStorQq) | C14: 서울특별시 / 서울신용보증재단 | D14: 2026 | E14: https://data.seoul.go.kr/dataList/OA-15577/S/1/datasetView.do | F14: public_data | G14: Store counts incl. franchise and open/close; 대학로 한식 191 (31 franchise) 2025Q4
A15: S14 | B15: 상권분석서비스 길단위인구-상권 (OA-15568) | C15: 서울특별시 / 서울신용보증재단 | D15: 2026 | E15: https://data.seoul.go.kr/dataList/OA-15568/S/1/datasetView.do | F15: public_data | G15: Foot traffic by age / time band / 요일; quarterly rows
A16: S15 | B16: 상권분석서비스 상주인구-상권 (OA-15584) | C16: 서울특별시 / 서울신용보증재단 | D16: 2026 | E16: https://data.seoul.go.kr/dataList/OA-15584/S/1/datasetView.do | F16: public_data | G16: Resident population; Q4 value repeats in next Q1-Q3
A17: S16 | B17: 상권분석서비스 직장인구-상권 (OA-15569) | C17: 서울특별시 / 서울신용보증재단 | D17: 2026 | E17: https://data.seoul.go.kr/dataList/OA-15569/S/1/datasetView.do | F17: public_data | G17: Worker population; Q4 value repeats in next Q1-Q3
A18: S17 | B18: 상권분석서비스 집객시설-상권 (OA-15580) | C18: 서울특별시 / 서울신용보증재단 | D18: 2026 | E18: https://data.seoul.go.kr/dataList/OA-15580/S/1/datasetView.do | F18: public_data | G18: Universities / subway / bus / theaters counts; yearly
A19: S18 | B19: 상권분석서비스 영역-상권 (OA-15560) | C19: 서울특별시 / 서울신용보증재단 | D19: 2026 | E19: https://data.seoul.go.kr/dataList/OA-15560/S/1/datasetView.do | F19: public_data | G19: 상권 polygons EPSG:5181; used for point-in-polygon
A20: S19 | B20: 상권분석서비스 상권변화지표-상권 (OA-15576) | C20: 서울특별시 / 서울신용보증재단 | D20: 2026 | E20: https://data.seoul.go.kr/dataList/OA-15576/S/1/datasetView.do | F20: public_data | G20: Change index; average months open / to closure
... A30: S29 | B30: 외식 평균 객단가 ₩14310 / 2024 외식업 매출 | C30: 뉴시스 | D30: 2026 | E30: https://www.newsis.com/view/NISX20260328_0003567838 | F30: news | G30: All-외식 averages; not comparable to BBQ ticket
A31: S30 | B31: 고기집 수익률 계산법 (65/20/15 매출 구조; 3회전+) | C31: moneycat.wandererkator.com (anonymous blog) | E31: https://moneycat.wandererkator.com/entry/%EA%B3%A0%EA%B8%B0%EC%A7%91-%EC%88%98%EC%9D%B5%EB%A5%A0-%EA%B3%84%EC%82%B0%EB%B2%95%EA%B3%BC-%EB%A7%A4%EC%B6%9C-%EA%B5%AC%EC%A1%B0-%EC%99%84%EB%B2%BD-%EC%A0%95%EB%A6%AC | F31: blog | G31: UNVERIFIED anonymous blog; only published meat/alcohol/meal split found; use as weak prior only
A32: S31 | B32: 외식업 경영실태 (한식 육류요리전문점 / 육류구이) C2020_77-6 | C32: KREI / 서울대 for 농식품부 | D32: 2020 | E32: https://repository.krei.re.kr/bitstream/2018.oak/26686/1/C2020_77-6.pdf | F32: report | G32: 2018 data; nationwide; cost shares of operating cost (식재료 41.0 / 인건비 34.2 / 임차 9.3) converted to revenue; OP 9.4% after imputed owner wage; 3.2 staff
A33: S32 | B33: KREI 외식업 경영실태 리플릿 2403 | C33: KREI | D33: 2024 | E33: https://www.krei.re.kr/namo/binary/files/000025/2403_Leflet_4.pdf | F33: report | G33: 2022 all-외식: 인건비 33.2% of cost (대표자 14.9 / 고용인 14.8 / 가족 3.5); 임차 9.6%; avg deposit ₩3301만
A34: S33 | B34: 외식업체 경영실태조사 (2024 data) | C34: 농림축산식품부 | E34: https://www.mafra.go.kr/bbs/home/792/577439/artclView.do | F34: report | G34: Press/summary level; all-외식 revenue ₩2.553억 (한식 ₩2.911억; non-franchise ₩2.3억); OP 8.7%; publication year not stated in research file
A35: S34 | B35: 30평 삼겹살 프랜차이즈 사례 (15테이블 60석) | C35: 한경비즈니스 | D35: 2021 | E35: https://magazine.hankyung.com/business/article/202103043150b | F35: news | G35: Single franchise case in 미금 (성남) not Seoul; ~₩3000만/월
A36: S35 | B36: 저녁 영업 삼겹살집 / 상위권 매장 매출 | C36: 머니투데이 | D36: 2022 | E36: https://www.mt.co.kr/culture/2022/09/01/2022090109505555998 | F36: news | G36: Anecdotal; evening-only 6h store; top-tier ₩9000만-1억 outliers
A37: S36 | B37: 2026 최저임금 ₩10320 (월 209h ₩2156880) | C37: bizforms 365guide | D37: 2026 | E37: https://www.bizforms.co.kr/365guide/view.asp?number=162 | F37: blog | G37: Statutory figure restated by a forms site; value matches the 2026 minimum wage decision
A38: S37 | B38: 프랜차이즈 고깃집 고매출 저이익 사례 | C38: 아시아경제 | D38: 2025 | E38: https://www.asiae.co.kr/visual-news/article/2025101015353443475 | F38: news | G38: Anecdotal outlier (~₩1억 revenue netting ~0)
A39: S38 | B39: 한식음식점 5년 생존율 34% (국세청 2023) | C39: 택스워치 | D39: 2025 | E39: https://www.taxwatch.co.kr/article/tax/2025/08/13/0002 | F39: news | G39: 사업자 폐업 basis (differs from 인허가 basis)
A40: S39 | B40: 100대 생활업종 생존율 (3년 53.8% / 5년 39.6%) | C40: 한국경제 | D40: 2025 | E40: https://www.hankyung.com/article/2025043073077 | F40: news | G40: National all-업종 average
A41: S40 | B41: 외식업 폐업률 2023 (서울 18.99%; 핀다 오픈업) | C41: 한경비즈니스 | D41: 2024 | E41: https://magazine.hankyung.com/business/article/202404281767b | F41: news | G41: Private data vendor estimate
A42: S41 | B42: 서울 2025 1분기 개업 8772 / 폐업 14988 | C42: 한국경제 | D42: 2025 | E42: https://www.hankyung.com/article/2025060190501 | F42: news | G42: Category scope unclear in the article
A43: S42 | B43: 2024 소상공인실태조사 발표 | C43: 파이낸셜뉴스 | D43: 2026 | E43: https://www.fnnews.com/news/202603130840507888 | F43: news | G43: 2024 survey dropped revenue/cost items; sector totals only
A44: S43 | B44: LOCALDATA 인허가 데이터 data.go.kr 이관 | C44: 경향신문 | D44: 2026 | E44: https://www.khan.co.kr/article/202601251400011/ | F44: news | G44: Context for data access only
A45: S44 | B45: 우리마을가게 상권분석서비스 | C45: 서울특별시 | D45: 2026 | E45: https://golmok.seoul.go.kr/ | F45: public_data | G45: Front end of S12-S19; no new data
A46: S45 | B46: 소상공인365 빅데이터 | C46: 소상공인시장진흥공단 | D46: 2026 | E46: https://bigdata.sbiz.or.kr/ | F46: public_data | G46: Web reports on S20; cross-check only
A47: S46 | B47: 상권분석서비스 소비-상권 (OA-21278) | C47: 서울특별시 / 서울신용보증재단 | D47: 2026 | E47: https://data.seoul.go.kr/dataList/OA-21278/S/1/datasetView.do | F47: public_data | G47: Spending totals only; income fields removed 2026-05-13; no longer updated
A48: S47 | B48: Restaurant RevPASH explainer | C48: SevenRooms blog | E48: https://sevenrooms.com/blog/restaurant-revpash/ | F48: blog | G48: Vendor blog; the RevPASH formula actually used came from this summary
A49: S48 | B49: 지난해 돈가 예측 왜 크게 빗나갔나? (지육 2024 평균 5,239 / 2025 평균 5,763원/kg) | C49: 양돈타임스 (pigpeople.net) | D49: 2026 | E49: https://pigpeople.net/news/article.html?no=18429 | F49: news | G49: Trade press; 축산물품질평가원 basis as reported; 지육 not 삼겹
...

Sheet Checks
A1: check_id | B1: 항목 | C1: 값 | D1: 하한 | E1: 상한 | F1: 결과 | G1: 설명
A2: C01 | B2: 월 매출이 prior ₩2,000–5,000만 안 | C2: ='P&L'!$B$19 | D2: =b_bm04_low | E2: =b_bm04_high | F2: =IF(AND(C2>=D2,C2<=E2),"PASS","FAIL") | G2: P&L 매출 vs Benchmarks BM04
A3: C02 | B3: 월 매출이 앵커 ±40% 안 (편차) | C3: ='P&L'!$B$19/b_bm03-1 | D3: -0.4 | E3: 0.4 | F3: =IF(AND(C3>=D3,C3<=E3),"PASS","FAIL") | G3: 앵커 = 대학로 한식 점포당 월매출 (BM03)
A4: C03 | B4: 식재료비 비중 vs KREI (pp) | C4: =('P&L'!$D$29-b_bm13)*100 | F4: INFO | G4: INFO: 고기 원가를 KMTA 시세로 바꾼 뒤 아래에서 쌓아 올린 값. KREI 2018 전국 비중은 목표가 아님. 반찬·식사 원가는 출처 없음
A5: C04 | B5: 인건비 비중 vs KREI (pp) | C5: =('P&L'!$D$33-b_bm15)*100 | D5: -5 | E5: 5 | F5: =IF(AND(C5>=D5,C5<=E5),"PASS","FAIL") | G5: ±5pp; 대표자 귀속 인건비 포함
A6: C05 | B6: 임차료 비중 vs KREI (pp) | C6: =('P&L'!$D$34-b_bm17)*100 | F6: INFO | G6: INFO: 혜화동 1층 임대료가 전국의 약 3배(BM45)라 전국 비용 비중이 맞지 않음. 오류가 아니라 이 상권의 특징
A7: C06 | B7: 관리비+수수료 비중 vs KREI 잔여 (pp) | C7: =('P&L'!$D$39-b_bm19)*100 | D7: -5 | E7: 5 | F7: =IF(AND(C7>=D7,C7<=E7),"PASS","FAIL") | G7: ±5pp; KREI 잔여 = 1 - 식재료 - 인건비 - 임차
A8: C07 | B8: 영업이익률 vs KREI (pp) | C8: =('P&L'!$D$42-b_bm11)*100 | D8: -5 | E8: 5 | F8: =IF(AND(C8>=D8,C8<=E8),"PASS","FAIL") | G8: ±5pp (추가 검사)
A9: C08 | B9: 주류 매출 비중 (참고 17–25%) | C9: ='P&L'!$D$21 | F9: INFO | G9: INFO: 17–25%는 미검증 블로그 범위. 식약처 음주량(S62)을 적용한 값이 더 낮음
A10: C09 | B10: HeroStore confidence 빈칸 수 | C10: =SUMPRODUCT(--(LEN(HeroStore!$J$2:$J$83)=0)) | D10: 0 | E10: 0 | F10: =IF(AND(C10>=D10,C10<=E10),"PASS","FAIL") | G10: 모든 행에 H/M/L
A11: C10 | B11: source_id 없는데 confidence ≠ L 인 행 수 | C11: =SUMPRODUCT((LEN(HeroStore!$I$2:$I$83)=0)*(HeroStore!$J$2:$J$83<>"L")) | D11: 0 | E11: 0 | F11: =IF(AND(C11>=D11,C11<=E11),"PASS","FAIL") | G11: 출처가 없으면 반드시 L
A12: C11 | B12: reasoning_chain 빈칸 수 | C12: =SUMPRODUCT(--(LEN(HeroStore!$H$2:$H$83)=0)) | D12: 0 | E12: 0 | F12: =IF(AND(C12>=D12,C12<=E12),"PASS","FAIL") | G12: 모든 행에 계산 근거 한 줄
A13: C12 | B13: source_id 없는 행 수 (L 가정값) | C13: =SUMPRODUCT(--(LEN(HeroStore!$I$2:$I$83)=0)) | F13: INFO | G13: INFO: 출처 확보 대상 목록
A14: C13 | B14: reviewed_by 빈칸 수 (검토 대기) | C14: =SUMPRODUCT(--(LEN(HeroStore!$L$2:$L$83)=0)) | F14: INFO | G14: INFO: 0이 될 때까지 사람이 검토
A15: C14 | B15: 값이 비어 있는 행 수 (파이프라인·인터뷰 대기) | C15: =SUMPRODUCT(--(LEN(HeroStore!$D$2:$D$83)=0)) | F15: INFO | G15: INFO
B17: 전체 결과 | F17: =IF(COUNTIF(F2:F15,"FAIL")=0,"ALL PASS","FAIL 있음")

Sheet ChangeLog
A1: criterion_id | B1: field | C1: old | D1: new | E1: source_id | F1: reviewed_by | G1: date | H1: patch
